2022-07-03 09:12:22 WARNING (SyncWorker_0) [homeassistant.loader] We found a custom integration hacs which has not been tested by Home Assistant. This component might cause stability problems, be sure to disable it if you experience issues with Home Assistant
2022-07-03 09:12:22 WARNING (SyncWorker_3) [homeassistant.loader] We found a custom integration alexa_media which has not been tested by Home Assistant. This component might cause stability problems, be sure to disable it if you experience issues with Home Assistant
2022-07-03 09:12:22 WARNING (SyncWorker_1) [homeassistant.loader] We found a custom integration scheduler which has not been tested by Home Assistant. This component might cause stability problems, be sure to disable it if you experience issues with Home Assistant
2022-07-03 09:12:22 WARNING (SyncWorker_2) [homeassistant.loader] We found a custom integration breaking_changes which has not been tested by Home Assistant. This component might cause stability problems, be sure to disable it if you experience issues with Home Assistant
2022-07-03 09:12:22 ERROR (SyncWorker_2) [homeassistant.loader] The custom integration 'breaking_changes' does not have a version key in the manifest file and was blocked from loading. See https://developers.home-assistant.io/blog/2021/01/29/custom-integration-changes#versions for more details
2022-07-03 09:12:22 WARNING (SyncWorker_0) [homeassistant.loader] We found a custom integration nodered which has not been tested by Home Assistant. This component might cause stability problems, be sure to disable it if you experience issues with Home Assistant
2022-07-03 09:12:24 WARNING (MainThread) [homeassistant.components.mqtt.mixins] Manually configured MQTT cover(s) found under platform key 'cover', please move to the mqtt integration key, see https://www.home-assistant.io/integrations/cover.mqtt/#new_format
2022-07-03 09:12:25 WARNING (MainThread) [homeassistant.components.mqtt.mixins] Manually configured MQTT switch(s) found under platform key 'switch', please move to the mqtt integration key, see https://www.home-assistant.io/integrations/switch.mqtt/#new_format
2022-07-03 09:12:26 WARNING (MainThread) [homeassistant.helpers.template] Template variable warning: 'None' has no attribute 'state' when rendering '/local/moon_phases/{{ states.sensor.moon.state }}.png'
2022-07-03 09:12:29 WARNING (MainThread) [homeassistant.config_entries] Config entry '10.0.10.5' for octoprint integration not ready yet: Cannot connect to host 10.0.10.5:80 ssl:default [Connect call failed ('10.0.10.5', 80)]; Retrying in background
2022-07-03 09:15:02 ERROR (MainThread) [homeassistant.util.logging] Exception in options_updated when dispatching 'unifi-options-5f86ce66a90cd009dbe96ff9aff8504f': ()
Traceback (most recent call last):
  File "/usr/src/homeassistant/homeassistant/components/unifi/device_tracker.py", line 328, in options_updated
    await self.remove_item({self.client.mac})
  File "/usr/src/homeassistant/homeassistant/components/unifi/unifi_entity_base.py", line 86, in remove_item
    er.async_get(self.hass).async_remove(self.entity_id)
  File "/usr/src/homeassistant/homeassistant/helpers/entity_registry.py", line 415, in async_remove
    self.entities.pop(entity_id)
  File "/usr/local/lib/python3.9/_collections_abc.py", line 904, in pop
    value = self[key]
  File "/usr/local/lib/python3.9/collections/__init__.py", line 1058, in __getitem__
    raise KeyError(key)
KeyError: 'device_tracker.cam_garage_inside'

2022-07-03 09:15:02 ERROR (MainThread) [homeassistant.util.logging] Exception in options_updated when dispatching 'unifi-options-5f86ce66a90cd009dbe96ff9aff8504f': ()
Traceback (most recent call last):
  File "/usr/src/homeassistant/homeassistant/components/unifi/device_tracker.py", line 328, in options_updated
    await self.remove_item({self.client.mac})
  File "/usr/src/homeassistant/homeassistant/components/unifi/unifi_entity_base.py", line 86, in remove_item
    er.async_get(self.hass).async_remove(self.entity_id)
  File "/usr/src/homeassistant/homeassistant/helpers/entity_registry.py", line 415, in async_remove
    self.entities.pop(entity_id)
  File "/usr/local/lib/python3.9/_collections_abc.py", line 904, in pop
    value = self[key]
  File "/usr/local/lib/python3.9/collections/__init__.py", line 1058, in __getitem__
    raise KeyError(key)
KeyError: 'device_tracker.cam_parlor_inside'

2022-07-03 09:15:02 ERROR (MainThread) [homeassistant.util.logging] Exception in options_updated when dispatching 'unifi-options-5f86ce66a90cd009dbe96ff9aff8504f': ()
Traceback (most recent call last):
  File "/usr/src/homeassistant/homeassistant/components/unifi/device_tracker.py", line 328, in options_updated
    await self.remove_item({self.client.mac})
  File "/usr/src/homeassistant/homeassistant/components/unifi/unifi_entity_base.py", line 86, in remove_item
    er.async_get(self.hass).async_remove(self.entity_id)
  File "/usr/src/homeassistant/homeassistant/helpers/entity_registry.py", line 415, in async_remove
    self.entities.pop(entity_id)
  File "/usr/local/lib/python3.9/_collections_abc.py", line 904, in pop
    value = self[key]
  File "/usr/local/lib/python3.9/collections/__init__.py", line 1058, in __getitem__
    raise KeyError(key)
KeyError: 'device_tracker.cam_porch_outside'

2022-07-03 09:15:02 ERROR (MainThread) [homeassistant.util.logging] Exception in options_updated when dispatching 'unifi-options-5f86ce66a90cd009dbe96ff9aff8504f': ()
Traceback (most recent call last):
  File "/usr/src/homeassistant/homeassistant/components/unifi/device_tracker.py", line 328, in options_updated
    await self.remove_item({self.client.mac})
  File "/usr/src/homeassistant/homeassistant/components/unifi/unifi_entity_base.py", line 86, in remove_item
    er.async_get(self.hass).async_remove(self.entity_id)
  File "/usr/src/homeassistant/homeassistant/helpers/entity_registry.py", line 415, in async_remove
    self.entities.pop(entity_id)
  File "/usr/local/lib/python3.9/_collections_abc.py", line 904, in pop
    value = self[key]
  File "/usr/local/lib/python3.9/collections/__init__.py", line 1058, in __getitem__
    raise KeyError(key)
KeyError: 'device_tracker.camera_backyard_n_outside'

2022-07-03 09:15:02 ERROR (MainThread) [homeassistant.util.logging] Exception in options_updated when dispatching 'unifi-options-5f86ce66a90cd009dbe96ff9aff8504f': ()
Traceback (most recent call last):
  File "/usr/src/homeassistant/homeassistant/components/unifi/device_tracker.py", line 328, in options_updated
    await self.remove_item({self.client.mac})
  File "/usr/src/homeassistant/homeassistant/components/unifi/unifi_entity_base.py", line 86, in remove_item
    er.async_get(self.hass).async_remove(self.entity_id)
  File "/usr/src/homeassistant/homeassistant/helpers/entity_registry.py", line 415, in async_remove
    self.entities.pop(entity_id)
  File "/usr/local/lib/python3.9/_collections_abc.py", line 904, in pop
    value = self[key]
  File "/usr/local/lib/python3.9/collections/__init__.py", line 1058, in __getitem__
    raise KeyError(key)
KeyError: 'device_tracker.cam_driveway_outside'

2022-07-03 09:15:02 ERROR (MainThread) [homeassistant.util.logging] Exception in options_updated when dispatching 'unifi-options-5f86ce66a90cd009dbe96ff9aff8504f': ()
Traceback (most recent call last):
  File "/usr/src/homeassistant/homeassistant/components/unifi/device_tracker.py", line 464, in options_updated
    await self.remove_item({self.device.mac})
  File "/usr/src/homeassistant/homeassistant/components/unifi/unifi_entity_base.py", line 86, in remove_item
    er.async_get(self.hass).async_remove(self.entity_id)
  File "/usr/src/homeassistant/homeassistant/helpers/entity_registry.py", line 415, in async_remove
    self.entities.pop(entity_id)
  File "/usr/local/lib/python3.9/_collections_abc.py", line 904, in pop
    value = self[key]
  File "/usr/local/lib/python3.9/collections/__init__.py", line 1058, in __getitem__
    raise KeyError(key)
KeyError: 'device_tracker.udm_pro'

2022-07-03 09:15:02 ERROR (MainThread) [homeassistant.util.logging] Exception in options_updated when dispatching 'unifi-options-5f86ce66a90cd009dbe96ff9aff8504f': ()
Traceback (most recent call last):
  File "/usr/src/homeassistant/homeassistant/components/unifi/device_tracker.py", line 464, in options_updated
    await self.remove_item({self.device.mac})
  File "/usr/src/homeassistant/homeassistant/components/unifi/unifi_entity_base.py", line 86, in remove_item
    er.async_get(self.hass).async_remove(self.entity_id)
  File "/usr/src/homeassistant/homeassistant/helpers/entity_registry.py", line 415, in async_remove
    self.entities.pop(entity_id)
  File "/usr/local/lib/python3.9/_collections_abc.py", line 904, in pop
    value = self[key]
  File "/usr/local/lib/python3.9/collections/__init__.py", line 1058, in __getitem__
    raise KeyError(key)
KeyError: 'device_tracker.bsmt_ap'

2022-07-03 09:15:02 ERROR (MainThread) [homeassistant.util.logging] Exception in options_updated when dispatching 'unifi-options-5f86ce66a90cd009dbe96ff9aff8504f': ()
Traceback (most recent call last):
  File "/usr/src/homeassistant/homeassistant/components/unifi/device_tracker.py", line 464, in options_updated
    await self.remove_item({self.device.mac})
  File "/usr/src/homeassistant/homeassistant/components/unifi/unifi_entity_base.py", line 86, in remove_item
    er.async_get(self.hass).async_remove(self.entity_id)
  File "/usr/src/homeassistant/homeassistant/helpers/entity_registry.py", line 415, in async_remove
    self.entities.pop(entity_id)
  File "/usr/local/lib/python3.9/_collections_abc.py", line 904, in pop
    value = self[key]
  File "/usr/local/lib/python3.9/collections/__init__.py", line 1058, in __getitem__
    raise KeyError(key)
KeyError: 'device_tracker.2flr_ap'

2022-07-03 09:15:02 ERROR (MainThread) [homeassistant.util.logging] Exception in options_updated when dispatching 'unifi-options-5f86ce66a90cd009dbe96ff9aff8504f': ()
Traceback (most recent call last):
  File "/usr/src/homeassistant/homeassistant/components/unifi/device_tracker.py", line 464, in options_updated
    await self.remove_item({self.device.mac})
  File "/usr/src/homeassistant/homeassistant/components/unifi/unifi_entity_base.py", line 86, in remove_item
    er.async_get(self.hass).async_remove(self.entity_id)
  File "/usr/src/homeassistant/homeassistant/helpers/entity_registry.py", line 415, in async_remove
    self.entities.pop(entity_id)
  File "/usr/local/lib/python3.9/_collections_abc.py", line 904, in pop
    value = self[key]
  File "/usr/local/lib/python3.9/collections/__init__.py", line 1058, in __getitem__
    raise KeyError(key)
KeyError: 'device_tracker.core_sw'

